<?xml version="1.0" encoding="utf-8"?>
<!-- This URDF was automatically created by SolidWorks to URDF Exporter! Originally created by Stephen Brawner (brawner@gmail.com) 
     Commit Version: 1.6.0-4-g7f85cfe  Build Version: 1.6.7995.38578
     For more information, please see http://wiki.ros.org/sw_urdf_exporter -->
<robot
  name="Baugr1_neu">
  <link
    name="base_link">
    <inertial>
      <origin
        xyz="-2.77555756156289E-17 -0.010014813474129 -1.38777878078145E-17"
        rpy="0 0 0" />
      <mass
        value="0.198821902754904" />
      <inertia
        ixx="0.000173296474165141"
        ixy="-1.18377987230202E-20"
        ixz="5.98344073940438E-20"
        iyy="0.000333318607117769"
        iyz="-2.7905190722586E-21"
        izz="0.000173296474165141" />
    </inertial>
    <visual>
      <origin
        xyz="0 0 0"
        rpy="0 0 0" />
      <geometry>
        <mesh
          filename="package://Baugr1_neu/meshes/base_link.STL" />
      </geometry>
      <material
        name="">
        <color
          rgba="0.792156862745098 0.819607843137255 0.933333333333333 1" />
      </material>
    </visual>
    <collision>
      <origin
        xyz="0 0 0"
        rpy="0 0 0" />
      <geometry>
        <mesh
          filename="package://Baugr1_neu/meshes/base_link.STL" />
      </geometry>
    </collision>
  </link>
  <link
    name="mast">
    <inertial>
      <origin
        xyz="-2.77555756156289E-17 1.38777878078145E-17 -0.00990334808044974"
        rpy="0 0 0" />
      <mass
        value="0.146997165855957" />
      <inertia
        ixx="0.00165530089499019"
        ixy="-1.6940658945086E-20"
        ixz="-9.05909129000529E-20"
        iyy="0.00151558687029216"
        iyz="5.69219397412074E-20"
        izz="0.000168947179064957" />
    </inertial>
    <visual>
      <origin
        xyz="0 0 0"
        rpy="0 0 0" />
      <geometry>
        <mesh
          filename="package://Baugr1_neu/meshes/mast.STL" />
      </geometry>
      <material
        name="">
        <color
          rgba="0.792156862745098 0.819607843137255 0.933333333333333 1" />
      </material>
    </visual>
    <collision>
      <origin
        xyz="0 0 0"
        rpy="0 0 0" />
      <geometry>
        <mesh
          filename="package://Baugr1_neu/meshes/mast.STL" />
      </geometry>
    </collision>
  </link>
  <joint
    name="mast"
    type="continuous">
    <origin
      xyz="0 0.325 0"
      rpy="1.5707963267949 0.0302496115811473 0" />
    <parent
      link="base_link" />
    <child
      link="mast" />
    <axis
      xyz="0 0 1" />
    <limit
      lower="0"
      upper="0"
      effort="0"
      velocity="0" />
  </joint>
  <link
    name="arm">
    <inertial>
      <origin
        xyz="-0.034802820992966 -0.0305629778991205 -0.0053633608313837"
        rpy="0 0 0" />
      <mass
        value="0.670566481180146" />
      <inertia
        ixx="0.000221577080037879"
        ixy="0.000117365608493163"
        ixz="-4.05813694804121E-07"
        iyy="0.0221326364583199"
        iyz="-1.41524054076888E-06"
        izz="0.0221979713787108" />
    </inertial>
    <visual>
      <origin
        xyz="0 0 0"
        rpy="0 0 0" />
      <geometry>
        <mesh
          filename="package://Baugr1_neu/meshes/arm.STL" />
      </geometry>
      <material
        name="">
        <color
          rgba="0.792156862745098 0.819607843137255 0.933333333333333 1" />
      </material>
    </visual>
    <collision>
      <origin
        xyz="0 0 0"
        rpy="0 0 0" />
      <geometry>
        <mesh
          filename="package://Baugr1_neu/meshes/arm.STL" />
      </geometry>
    </collision>
  </link>
  <joint
    name="arm"
    type="continuous">
    <origin
      xyz="0 0 -0.109"
      rpy="-1.5707963267949 -0.141106709405523 0" />
    <parent
      link="mast" />
    <child
      link="arm" />
    <axis
      xyz="0 0 -1" />
    <limit
      lower="0"
      upper="0"
      effort="0"
      velocity="0" />
  </joint>
  <link
    name="heli">
    <inertial>
      <origin
        xyz="-7.17481629664007E-15 0.0329530083690057 -8.04911692853238E-15"
        rpy="0 0 0" />
      <mass
        value="2.53244229880151" />
      <inertia
        ixx="0.00741298241473207"
        ixy="1.0842021724855E-18"
        ixz="2.85958322993052E-18"
        iyy="0.0174840510486902"
        iyz="5.57008866114428E-18"
        izz="0.0104731788262659" />
    </inertial>
    <visual>
      <origin
        xyz="0 0 0"
        rpy="0 0 0" />
      <geometry>
        <mesh
          filename="package://Baugr1_neu/meshes/heli.STL" />
      </geometry>
      <material
        name="">
        <color
          rgba="0.792156862745098 0.819607843137255 0.933333333333333 1" />
      </material>
    </visual>
    <collision>
      <origin
        xyz="0 0 0"
        rpy="0 0 0" />
      <geometry>
        <mesh
          filename="package://Baugr1_neu/meshes/heli.STL" />
      </geometry>
    </collision>
  </link>
  <joint
    name="heli"
    type="continuous">
    <origin
      xyz="0.635999999999999 -0.0890000000000002 0"
      rpy="-1.5707963267949 -1.08914028989554 1.5707963267949" />
    <parent
      link="arm" />
    <child
      link="heli" />
    <axis
      xyz="0 0 -1" />
    <limit
      lower="0"
      upper="0"
      effort="0"
      velocity="0" />
  </joint>
</robot>